<?xml version="1.0" ?>
<!-- =================================================================================== -->
<!-- |    This document was autogenerated by xacro from allegro_hand_description_right.xacro | -->
<!-- |    EDITING THIS FILE BY HAND IS NOT RECOMMENDED                                 | -->
<!-- =================================================================================== -->
<robot name="allegro_hand_right" xmlns:xacro="http://www.ros.org/wiki/xacro">
    <!--
  rosrun xacro xacro.py allegro_hand_description_right.urdf.xacro > allegro_hand_description_right.urdf
  roslaunch launchers/fuerte/allegro_hand_jgui_right_virtual.launch
  -->
    <!-- ======================== BASE PARAMS ========================= -->
    <!-- ======================== FINGER PARAMS ======================== -->
    <!-- full height from joint to tip. when used,
  the radius of the finger tip sphere will be subtracted
  and one fixed link will be added for the tip. -->
    <!--0.0435,   0.044981-->
    <!--0.002298-->
    <!--0.002298-->
    <!-- ========================= THUMB PARAMS ========================= -->
    <!-- ========================= LIMITS ========================= -->
    <!-- ============================================================================= -->
    <!-- ============================================================================= -->
    <!-- ============================================================================= -->
    <!-- BASE -->
    <link name="base_link">
        <visual>
            <geometry>
                <mesh filename="package://allegro_hand_description/meshes/base_link.stl"/>
            </geometry>
            <origin rpy="0 0 0" xyz="0 0 0 "/>
            <material name="black">
                <color rgba="0.2 0.2 0.2 1"/>
            </material>
        </visual>

        <collision>
            <origin rpy="0 0 0" xyz="-0.009300 0 -0.0475"/>
            <geometry>
                <box size="0.0408 0.1130 0.095"/>
            </geometry>
        </collision>
    </link>
    <!-- ============================================================================= -->
    <!-- FINGERS -->

    <!-- BEGIN INDEX FINGER -->

    <joint name="right_index_twist_joint" type="revolute">
        <axis xyz="0 0 1"/>
        <limit effort="0.7" lower="-0.47" upper="0.47" velocity="6.283"/>
        <parent link="base_link"/>
        <child link="right_index_metacarpal_link"/>
        <origin rpy="-0.08726646255 0 0" xyz="0 0.0435 -0.001542"/>
    </joint>

    <link name="right_index_metacarpal_link">
        <visual>
            <geometry>
                <mesh filename="package://allegro_hand_description/meshes/0_metacarpal.stl"/>
            </geometry>
            <material name="black"/>
        </visual>

        <collision>
            <geometry>
                <box size="0.0196 0.0275 0.0164"/>
            </geometry>
            <origin rpy="0 0 0" xyz="0 0 0.0082"/>
        </collision>

        <inertial>
            <mass value="0.0119"/>
            <inertia ixx="0.001" ixy="0.0" ixz="0.0" iyy="0.001" iyz="0.0" izz="0.001"/>
            <origin rpy="0 0 0" xyz="0 0 0.0082"/>
        </inertial>
    </link>

    <joint name="right_index_proximal_joint" type="revolute">
        <limit effort="0.7" lower="-0.196" upper="1.61" velocity="6.283"/>
        <axis xyz="0 1 0"/>
        <parent link="right_index_metacarpal_link"/>
        <child link="right_index_proximal_link"/>
        <origin xyz="0 0 0.0164"/>
    </joint>

    <link name="right_index_proximal_link">
        <visual>
            <geometry>
                <mesh filename="package://allegro_hand_description/meshes/1_proximal.stl"/>
            </geometry>
            <material name="black"/>
        </visual>

        <collision>
            <geometry>
                <box size="0.0196 0.0275 0.054"/>
            </geometry>
            <origin rpy="0 0 0" xyz="0 0 0.027"/>
        </collision>

        <inertial>
            <mass value="0.065"/>
            <inertia ixx="0.001" ixy="0.0" ixz="0.0" iyy="0.001" iyz="0.0" izz="0.001"/>
            <origin rpy="0 0 0" xyz="0 0 0.0325"/>
        </inertial>
    </link>

    <joint name="right_index_middle_joint" type="revolute">
        <axis xyz="0 1 0"/>
        <limit effort="0.7" lower="-0.174" upper="1.709" velocity="6.283"/>
        <parent link="right_index_proximal_link"/>
        <child link="right_index_middle_link"/>
        <origin xyz="0 0 0.054"/>
    </joint>

    <link name="right_index_middle_link">
        <visual>
            <geometry>
                <mesh filename="package://allegro_hand_description/meshes/2_middle.stl"/>
            </geometry>
            <material name="black"/>
        </visual>

        <collision>
            <geometry>
                <box size="0.0196 0.0275 0.0384"/>
            </geometry>
            <origin rpy="0 0 0" xyz="0 0 0.0192"/>
        </collision>

        <inertial>
            <mass value="0.0355"/>
            <inertia ixx="0.001" ixy="0.0" ixz="0.0" iyy="0.001" iyz="0.0" izz="0.001"/>
            <origin rpy="0 0 0" xyz="0 0 0.017525"/>
        </inertial>
    </link>

    <joint name="right_index_distal_joint" type="revolute">
        <axis xyz="0 1 0"/>
        <limit effort="0.7" lower="-0.227" upper="1.618" velocity="6.283"/>
        <parent link="right_index_middle_link"/>
        <child link="right_index_distal_link"/>
        <origin xyz="0 0 0.0384"/>
    </joint>

    <link name="right_index_distal_link">
        <visual>
            <geometry>
                <mesh filename="package://allegro_hand_description/meshes/3_distal.stl"/>
            </geometry>
            <material name="black"/>
        </visual>

        <collision>
            <geometry>
                <box size="0.0196 0.0275 0.0267"/>
            </geometry>
            <origin rpy="0 0 0" xyz="0 0 0.01335"/>
        </collision>

        <inertial>
            <mass value="0.0096"/>
            <inertia ixx="0.001" ixy="0.0" ixz="0.0" iyy="0.001" iyz="0.0" izz="0.001"/>
            <origin rpy="0 0 0" xyz="0 0 0.0048"/>
        </inertial>
    </link>

    <joint name="right_index_tip_fixedjoint" type="fixed">
        <parent link="right_index_distal_link"/>
        <child link="right_index_tip_link"/>
        <origin rpy="0 0 0" xyz="0 0 0.0267"/>
    </joint>

    <link name="right_index_tip_link">
        <visual>
            <geometry>
                <mesh filename="package://allegro_hand_description/meshes/4_tip.stl"/>
            </geometry>
            <material name="white">
                <color rgba=".9 .9 .9 1"/>
            </material>
        </visual>

        <collision>
            <geometry>
                <sphere radius="0.012"/>
            </geometry>
        </collision>

        <inertial>
            <mass value="0.060"/>
            <inertia ixx="0.001" ixy="0.0" ixz="0.0" iyy="0.001" iyz="0.0" izz="0.001"/>
            <origin rpy="0 0 0" xyz="0 0 0.006"/>
        </inertial>
    </link>

    <!-- END INDEX FINGER -->

    <!-- BEGIN MIDDLE FINGER -->

    <joint name="right_middle_twist_joint" type="revolute">
        <axis xyz="0 0 1"/>
        <limit effort="0.7" lower="-0.47" upper="0.47" velocity="6.283"/>
        <parent link="base_link"/>
        <child link="right_middle_metacarpal_link"/>
        <origin rpy="0.0 0 0" xyz="0 0 0.0007"/>
    </joint>

    <link name="right_middle_metacarpal_link">
        <visual>
            <geometry>
                <mesh filename="package://allegro_hand_description/meshes/0_metacarpal.stl"/>
            </geometry>
            <material name="black"/>
        </visual>

        <collision>
            <geometry>
                <box size="0.0196 0.0275 0.0164"/>
            </geometry>
            <origin rpy="0 0 0" xyz="0 0 0.0082"/>
        </collision>

        <inertial>
            <mass value="0.0119"/>
            <inertia ixx="0.001" ixy="0.0" ixz="0.0" iyy="0.001" iyz="0.0" izz="0.001"/>
            <origin rpy="0 0 0" xyz="0 0 0.0082"/>
        </inertial>
    </link>

    <joint name="right_middle_proximal_joint" type="revolute">
        <limit effort="0.7" lower="-0.196" upper="1.61" velocity="6.283"/>
        <axis xyz="0 1 0"/>
        <parent link="right_middle_metacarpal_link"/>
        <child link="right_middle_proximal_link"/>
        <origin xyz="0 0 0.0164"/>
    </joint>

    <link name="right_middle_proximal_link">
        <visual>
            <geometry>
                <mesh filename="package://allegro_hand_description/meshes/1_proximal.stl"/>
            </geometry>
            <material name="black"/>
        </visual>

        <collision>
            <geometry>
                <box size="0.0196 0.0275 0.054"/>
            </geometry>
            <origin rpy="0 0 0" xyz="0 0 0.027"/>
        </collision>

        <inertial>
            <mass value="0.065"/>
            <inertia ixx="0.001" ixy="0.0" ixz="0.0" iyy="0.001" iyz="0.0" izz="0.001"/>
            <origin rpy="0 0 0" xyz="0 0 0.0325"/>
        </inertial>
    </link>

    <joint name="right_middle_middle_joint" type="revolute">
        <axis xyz="0 1 0"/>
        <limit effort="0.7" lower="-0.174" upper="1.709" velocity="6.283"/>
        <parent link="right_middle_proximal_link"/>
        <child link="right_middle_middle_link"/>
        <origin xyz="0 0 0.054"/>
    </joint>

    <link name="right_middle_middle_link">
        <visual>
            <geometry>
                <mesh filename="package://allegro_hand_description/meshes/2_middle.stl"/>
            </geometry>
            <material name="black"/>
        </visual>

        <collision>
            <geometry>
                <box size="0.0196 0.0275 0.0384"/>
            </geometry>
            <origin rpy="0 0 0" xyz="0 0 0.0192"/>
        </collision>

        <inertial>
            <mass value="0.0355"/>
            <inertia ixx="0.001" ixy="0.0" ixz="0.0" iyy="0.001" iyz="0.0" izz="0.001"/>
            <origin rpy="0 0 0" xyz="0 0 0.017525"/>
        </inertial>
    </link>

    <joint name="right_middle_distal_joint" type="revolute">
        <axis xyz="0 1 0"/>
        <limit effort="0.7" lower="-0.227" upper="1.618" velocity="6.283"/>
        <parent link="right_middle_middle_link"/>
        <child link="right_middle_distal_link"/>
        <origin xyz="0 0 0.0384"/>
    </joint>

    <link name="right_middle_distal_link">
        <visual>
            <geometry>
                <mesh filename="package://allegro_hand_description/meshes/3_distal.stl"/>
            </geometry>
            <material name="black"/>
        </visual>

        <collision>
            <geometry>
                <box size="0.0196 0.0275 0.0267"/>
            </geometry>
            <origin rpy="0 0 0" xyz="0 0 0.01335"/>
        </collision>

        <inertial>
            <mass value="0.0096"/>
            <inertia ixx="0.001" ixy="0.0" ixz="0.0" iyy="0.001" iyz="0.0" izz="0.001"/>
            <origin rpy="0 0 0" xyz="0 0 0.0048"/>
        </inertial>
    </link>

    <joint name="right_middle_tip_fixedjoint" type="fixed">
        <parent link="right_middle_distal_link"/>
        <child link="right_middle_tip_link"/>
        <origin rpy="0 0 0" xyz="0 0 0.0267"/>
    </joint>

    <link name="right_middle_tip_link">
        <visual>
            <geometry>
                <mesh filename="package://allegro_hand_description/meshes/4_tip.stl"/>
            </geometry>
            <material name="white">
                <color rgba=".9 .9 .9 1"/>
            </material>
        </visual>

        <collision>
            <geometry>
                <sphere radius="0.012"/>
            </geometry>
        </collision>

        <inertial>
            <mass value="0.060"/>
            <inertia ixx="0.001" ixy="0.0" ixz="0.0" iyy="0.001" iyz="0.0" izz="0.001"/>
            <origin rpy="0 0 0" xyz="0 0 0.006"/>
        </inertial>
    </link>

    <!-- END MIDDLE FINGER -->

    <!-- BEGIN SMALL FINGER -->

    <joint name="right_small_twist_joint" type="revolute">
        <axis xyz="0 0 1"/>
        <limit effort="0.7" lower="-0.47" upper="0.47" velocity="6.283"/>
        <parent link="base_link"/>
        <child link="right_small_metacarpal_link"/>
        <origin rpy="0.08726646255 0 0" xyz="0 -0.0435 -0.001542"/>
    </joint>

    <link name="right_small_metacarpal_link">
        <visual>
            <geometry>
                <mesh filename="package://allegro_hand_description/meshes/0_metacarpal.stl"/>
            </geometry>
            <material name="black"/>
        </visual>

        <collision>
            <geometry>
                <box size="0.0196 0.0275 0.0164"/>
            </geometry>
            <origin rpy="0 0 0" xyz="0 0 0.0082"/>
        </collision>

        <inertial>
            <mass value="0.0119"/>
            <inertia ixx="0.001" ixy="0.0" ixz="0.0" iyy="0.001" iyz="0.0" izz="0.001"/>
            <origin rpy="0 0 0" xyz="0 0 0.0082"/>
        </inertial>
    </link>

    <joint name="right_small_proximal_joint" type="revolute">
        <limit effort="0.7" lower="-0.196" upper="1.61" velocity="6.283"/>
        <axis xyz="0 1 0"/>
        <parent link="right_small_metacarpal_link"/>
        <child link="right_small_proximal_link"/>
        <origin xyz="0 0 0.0164"/>
    </joint>

    <link name="right_small_proximal_link">
        <visual>
            <geometry>
                <mesh filename="package://allegro_hand_description/meshes/1_proximal.stl"/>
            </geometry>
            <material name="black"/>
        </visual>

        <collision>
            <geometry>
                <box size="0.0196 0.0275 0.054"/>
            </geometry>
            <origin rpy="0 0 0" xyz="0 0 0.027"/>
        </collision>

        <inertial>
            <mass value="0.065"/>
            <inertia ixx="0.001" ixy="0.0" ixz="0.0" iyy="0.001" iyz="0.0" izz="0.001"/>
            <origin rpy="0 0 0" xyz="0 0 0.0325"/>
        </inertial>
    </link>

    <joint name="right_small_middle_joint" type="revolute">
        <axis xyz="0 1 0"/>
        <limit effort="0.7" lower="-0.174" upper="1.709" velocity="6.283"/>
        <parent link="right_small_proximal_link"/>
        <child link="right_small_middle_link"/>
        <origin xyz="0 0 0.054"/>
    </joint>

    <link name="right_small_middle_link">
        <visual>
            <geometry>
                <mesh filename="package://allegro_hand_description/meshes/2_middle.stl"/>
            </geometry>
            <material name="black"/>
        </visual>

        <collision>
            <geometry>
                <box size="0.0196 0.0275 0.0384"/>
            </geometry>
            <origin rpy="0 0 0" xyz="0 0 0.0192"/>
        </collision>

        <inertial>
            <mass value="0.0355"/>
            <inertia ixx="0.001" ixy="0.0" ixz="0.0" iyy="0.001" iyz="0.0" izz="0.001"/>
            <origin rpy="0 0 0" xyz="0 0 0.017525"/>
        </inertial>
    </link>

    <joint name="right_small_distal_joint" type="revolute">
        <axis xyz="0 1 0"/>
        <limit effort="0.7" lower="-0.227" upper="1.618" velocity="6.283"/>
        <parent link="right_small_middle_link"/>
        <child link="right_small_distal_link"/>
        <origin xyz="0 0 0.0384"/>
    </joint>

    <link name="right_small_distal_link">
        <visual>
            <geometry>
                <mesh filename="package://allegro_hand_description/meshes/3_distal.stl"/>
            </geometry>
            <material name="black"/>
        </visual>

        <collision>
            <geometry>
                <box size="0.0196 0.0275 0.0267"/>
            </geometry>
            <origin rpy="0 0 0" xyz="0 0 0.01335"/>
        </collision>

        <inertial>
            <mass value="0.0096"/>
            <inertia ixx="0.001" ixy="0.0" ixz="0.0" iyy="0.001" iyz="0.0" izz="0.001"/>
            <origin rpy="0 0 0" xyz="0 0 0.0048"/>
        </inertial>
    </link>

    <joint name="right_small_tip_fixedjoint" type="fixed">
        <parent link="right_small_distal_link"/>
        <child link="right_small_tip_link"/>
        <origin rpy="0 0 0" xyz="0 0 0.0267"/>
    </joint>

    <link name="right_small_tip_link">
        <visual>
            <geometry>
                <mesh filename="package://allegro_hand_description/meshes/4_tip.stl"/>
            </geometry>
            <material name="white">
                <color rgba=".9 .9 .9 1"/>
            </material>
        </visual>

        <collision>
            <geometry>
                <sphere radius="0.012"/>
            </geometry>
        </collision>

        <inertial>
            <mass value="0.060"/>
            <inertia ixx="0.001" ixy="0.0" ixz="0.0" iyy="0.001" iyz="0.0" izz="0.001"/>
            <origin rpy="0 0 0" xyz="0 0 0.006"/>
        </inertial>
    </link>

    <!-- END SMALL FINGER -->

    <!-- BEGIN THUMB -->

    <joint name="right_thumb_proximal_joint" type="revolute">
        <axis xyz="-1 0 0"/>
        <limit effort="0.7" lower="0.263" upper="1.396" velocity="6.283"/>
        <parent link="base_link"/>
        <child link="right_thumb_metacarpal_link"/>
        <origin rpy="0 -1.65806278845 -1.5707963259" xyz="-0.0182 0.019333 -0.045987"/>
    </joint>

    <link name="right_thumb_metacarpal_link">
        <visual>
            <geometry>
                <mesh filename="package://allegro_hand_description/meshes/0_metacarpal_thumb.stl"/>
            </geometry>
            <material name="black">
                <color rgba=".2 .2 .2 1"/>
            </material>
        </visual>

        <collision>
            <geometry>
                <box size="0.0358 0.034 0.0455"/>
            </geometry>
            <origin rpy="0 0 0" xyz="-0.0179 0.009 0.0145"/>
        </collision>

        <inertial>
            <mass value="0.0876"/>
            <inertia ixx="0.001" ixy="0.0" ixz="0.0" iyy="0.001" iyz="0.0" izz="0.001"/>
            <origin rpy="0 0 0" xyz="0.0179 0.017 0.02275"/>
        </inertial>
    </link>

    <joint name="right_thumb_twist_joint" type="revolute">
        <axis xyz="0 0 1"/>
        <limit effort="0.7" lower="-0.105" upper="1.163" velocity="6.283"/>
        <parent link="right_thumb_metacarpal_link"/>
        <child link="right_thumb_proximal_link"/>
        <origin xyz="-0.027 0.005 0.0399"/>
    </joint>

    <link name="right_thumb_proximal_link">
        <visual>
            <geometry>
                <mesh filename="package://allegro_hand_description/meshes/1_proximal_thumb.stl"/>
            </geometry>
            <material name="black">
                <color rgba=".2 .2 .2 1"/>
            </material>
        </visual>

        <collision>
            <geometry>
                <box size="0.0196 0.0275 0.0177"/>
            </geometry>
            <origin rpy="0 0 0" xyz="0 0 0.00885"/>
        </collision>

        <inertial>
            <mass value="0.0519"/>
            <inertia ixx="0.001" ixy="0.0" ixz="0.0" iyy="0.001" iyz="0.0" izz="0.001"/>
            <origin rpy="0 0 0" xyz="0 0 0.00885"/>
        </inertial>
    </link>

    <joint name="right_thumb_middle_joint" type="revolute">
        <axis xyz="0 1 0"/>
        <limit effort="0.7" lower="-0.189" upper="1.644" velocity="6.283"/>
        <parent link="right_thumb_proximal_link"/>
        <child link="right_thumb_middle_link"/>
        <origin xyz="0 0 0.0177"/>
    </joint>

    <link name="right_thumb_middle_link">
        <visual>
            <geometry>
                <mesh filename="package://allegro_hand_description/meshes/2_middle_thumb.stl"/>
            </geometry>
            <material name="black">
            </material>
        </visual>
        <collision>
            <geometry>
                <box size="0.0196 0.0275 0.0514"/>
            </geometry>
            <origin rpy="0 0 0" xyz="0 0 0.0257"/>
        </collision>

        <inertial>
            <mass value="0.038"/>
            <inertia ixx="0.001" ixy="0.0" ixz="0.0" iyy="0.001" iyz="0.0" izz="0.001"/>
            <origin rpy="0 0 0" xyz="0 0 0.0257"/>
        </inertial>
    </link>

    <joint name="right_thumb_distal_joint" type="revolute">
        <axis xyz="0 1 0"/>
        <limit effort="0.7" lower="-0.162" upper="1.719" velocity="6.283"/>
        <parent link="right_thumb_middle_link"/>
        <child link="right_thumb_distal_link"/>
        <origin xyz="0 0 0.0514"/>
    </joint>

    <link name="right_thumb_distal_link">
        <visual>
            <geometry>
                <mesh filename="package://allegro_hand_description/meshes/3_distal_thumb.stl"/>
            </geometry>
            <material name="black">
            </material>
        </visual>

        <collision>
            <geometry>
                <box size="0.0196 0.0275 0.0423"/>
            </geometry>
            <origin rpy="0 0 0" xyz="0 0 0.02115"/>
        </collision>

        <inertial>
            <mass value="0.0388"/>
            <inertia ixx="0.001" ixy="0.0" ixz="0.0" iyy="0.001" iyz="0.0" izz="0.001"/>
            <origin rpy="0 0 0" xyz="0 0 0.02115"/>
        </inertial>
    </link>

    <joint name="right_thumb_tip_fixedjoint" type="fixed">
        <parent link="right_thumb_distal_link"/>
        <child link="right_thumb_tip_link"/>
        <origin rpy="0 0 0" xyz="0 0 0.0423"/>
    </joint>

    <link name="right_thumb_tip_link">
        <visual>
            <geometry>
                <mesh filename="package://allegro_hand_description/meshes/4_tip_thumb.stl"/>
            </geometry>
            <material name="white">
                <color rgba=".9 .9 .9 1"/>
            </material>
        </visual>

        <collision>
            <geometry>
                <sphere radius="0.012"/>
            </geometry>
            <origin rpy="0 0 0" xyz="0 0 0"/>
        </collision>

        <inertial>
            <mass value="0.060"/>
            <inertia ixx="0.001" ixy="0.0" ixz="0.0" iyy="0.001" iyz="0.0" izz="0.001"/>
            <origin rpy="0 0 0" xyz="0 0 0.006"/>
        </inertial>
    </link>

    <!-- END THUMB -->
</robot>
